<robot name="onshape">
<link name="hips_v2">
<visual>
<origin xyz="0 0 0" rpy="0 -0 0" />
<geometry>
<mesh filename="package://hips_v2.stl"/>
</geometry>
<material name="hips_v2_material">
<color rgba="0.615686 0.811765 0.929412 1.0"/>
</material>
</visual>
<collision>
<origin xyz="0 0 0" rpy="0 -0 0" />
<geometry>
<mesh filename="package://hips_v2.stl"/>
</geometry>
<material name="hips_v2_material">
<color rgba="0.615686 0.811765 0.929412 1.0"/>
</material>
</collision>
<inertial>
<origin xyz="9.61344e-18 5.21164e-18 0.115446" rpy="0 0 0"/>
<mass value="34.3235" />
<inertia ixx="0.255978" ixy="0"  ixz="0" iyy="0.369075" iyz="0" izz="0.320715" />
</inertial>
</link>

<link name="hip_joint">
<visual>
<origin xyz="0 0.1 -0.01" rpy="1.5708 1.5708 0" />
<geometry>
<mesh filename="package://hip_joint.stl"/>
</geometry>
<material name="hip_joint_material">
<color rgba="0.615686 0.811765 0.929412 1.0"/>
</material>
</visual>
<collision>
<origin xyz="0 0.1 -0.01" rpy="1.5708 1.5708 0" />
<geometry>
<mesh filename="package://hip_joint.stl"/>
</geometry>
<material name="hip_joint_material">
<color rgba="0.615686 0.811765 0.929412 1.0"/>
</material>
</collision>
<inertial>
<origin xyz="6.73972e-37 0.0240455 -0.0859545" rpy="0 0 0"/>
<mass value="15.0204" />
<inertia ixx="0.0781127" ixy="-0.0132823"  ixz="0" iyy="0.0781127" iyz="0" izz="0.0811233" />
</inertial>
</link>

<link name="joint_flat">
<visual>
<origin xyz="0 6.12323e-18 0" rpy="3.14159 -0 0" />
<geometry>
<mesh filename="package://joint_flat.stl"/>
</geometry>
<material name="joint_flat_material">
<color rgba="0.615686 0.811765 0.929412 1.0"/>
</material>
</visual>
<collision>
<origin xyz="0 6.12323e-18 0" rpy="3.14159 -0 0" />
<geometry>
<mesh filename="package://joint_flat.stl"/>
</geometry>
<material name="joint_flat_material">
<color rgba="0.615686 0.811765 0.929412 1.0"/>
</material>
</collision>
<inertial>
<origin xyz="-1.83967e-18 0.0279294 -0.0956494" rpy="0 0 0"/>
<mass value="10.8856" />
<inertia ixx="0.0674171" ixy="0"  ixz="0" iyy="0.0759085" iyz="0.00923416" izz="0.0431093" />
</inertial>
</link>

<link name="upper_leg_v2">
<visual>
<origin xyz="0 0.8 0" rpy="1.5708 1.5708 0" />
<geometry>
<mesh filename="package://upper_leg_v2.stl"/>
</geometry>
<material name="upper_leg_v2_material">
<color rgba="0.615686 0.811765 0.929412 1.0"/>
</material>
</visual>
<collision>
<origin xyz="0 0.8 0" rpy="1.5708 1.5708 0" />
<geometry>
<mesh filename="package://upper_leg_v2.stl"/>
</geometry>
<material name="upper_leg_v2_material">
<color rgba="0.615686 0.811765 0.929412 1.0"/>
</material>
</collision>
<inertial>
<origin xyz="6.34561e-18 0.380741 0.00760038" rpy="0 0 0"/>
<mass value="60.2057" />
<inertia ixx="0.417664" ixy="0.351619"  ixz="0" iyy="3.33483" iyz="0" izz="3.36634" />
</inertial>
</link>

<link name="knee">
<visual>
<origin xyz="0.1 -0.1 -0.05" rpy="-1.5708 -0 0" />
<geometry>
<mesh filename="package://knee.stl"/>
</geometry>
<material name="knee_material">
<color rgba="0.615686 0.811765 0.929412 1.0"/>
</material>
</visual>
<collision>
<origin xyz="0.1 -0.1 -0.05" rpy="-1.5708 -0 0" />
<geometry>
<mesh filename="package://knee.stl"/>
</geometry>
<material name="knee_material">
<color rgba="0.615686 0.811765 0.929412 1.0"/>
</material>
</collision>
<inertial>
<origin xyz="0.0942625 0.579418 -0.05" rpy="0 0 0"/>
<mass value="109.213" />
<inertia ixx="15.8239" ixy="0.363072"  ixz="-5.99837e-17" iyy="0.595768" iyz="2.53423e-15" izz="15.935" />
</inertial>
</link>

<joint name="right_knee" type="revolute">
<origin xyz="0.05 0.7 0.1" rpy="1.65212e-16 1.5708 0" />
<parent link="upper_leg_v2" />
<child link="knee" />
<axis xyz="0 0 1"/>
<limit effort="2000" velocity="20" lower="0" upper="3.05433"/>
<joint_properties friction="0.0"/>
</joint>

<joint name="right_leg3" type="revolute">
<origin xyz="5.55112e-17 6.12323e-18 -0.15" rpy="-1.5708 -0 0" />
<parent link="joint_flat" />
<child link="upper_leg_v2" />
<axis xyz="0 0 1"/>
<limit effort="1000" velocity="20" lower="-0.785398" upper="1.5708"/>
<joint_properties friction="0.0"/>
</joint>

<joint name="right_leg2" type="revolute">
<origin xyz="6.12323e-18 0.11 -0.11" rpy="1.5708 -1.5708 0" />
<parent link="hip_joint" />
<child link="joint_flat" />
<axis xyz="0 0 1"/>
<limit effort="1000" velocity="20" lower="-0.174533" upper="0.785398"/>
<joint_properties friction="0.0"/>
</joint>

<joint name="right_leg1" type="revolute">
<origin xyz="-0.15 0 0.1" rpy="-1.5708 -0 -1.5708" />
<parent link="hips_v2" />
<child link="hip_joint" />
<axis xyz="0 0 1"/>
<limit effort="1000" velocity="20" lower="-3.14159" upper="1.5708"/>
<joint_properties friction="0.0"/>
</joint>

<link name="hip_joint_2">
<visual>
<origin xyz="0 0.1 -0.01" rpy="1.5708 1.5708 0" />
<geometry>
<mesh filename="package://hip_joint.stl"/>
</geometry>
<material name="hip_joint_material">
<color rgba="0.615686 0.811765 0.929412 1.0"/>
</material>
</visual>
<collision>
<origin xyz="0 0.1 -0.01" rpy="1.5708 1.5708 0" />
<geometry>
<mesh filename="package://hip_joint.stl"/>
</geometry>
<material name="hip_joint_material">
<color rgba="0.615686 0.811765 0.929412 1.0"/>
</material>
</collision>
<inertial>
<origin xyz="6.73972e-37 0.0240455 -0.0859545" rpy="0 0 0"/>
<mass value="15.0204" />
<inertia ixx="0.0781127" ixy="-0.0132823"  ixz="0" iyy="0.0781127" iyz="0" izz="0.0811233" />
</inertial>
</link>

<link name="joint_flat_2">
<visual>
<origin xyz="0 6.12323e-18 0" rpy="3.14159 -0 2.75465e-52" />
<geometry>
<mesh filename="package://joint_flat.stl"/>
</geometry>
<material name="joint_flat_material">
<color rgba="0.615686 0.811765 0.929412 1.0"/>
</material>
</visual>
<collision>
<origin xyz="0 6.12323e-18 0" rpy="3.14159 -0 2.75465e-52" />
<geometry>
<mesh filename="package://joint_flat.stl"/>
</geometry>
<material name="joint_flat_material">
<color rgba="0.615686 0.811765 0.929412 1.0"/>
</material>
</collision>
<inertial>
<origin xyz="-1.83967e-18 0.0279294 -0.0956494" rpy="0 0 0"/>
<mass value="10.8856" />
<inertia ixx="0.0674171" ixy="-3.94812e-53"  ixz="-2.54369e-54" iyy="0.0759085" iyz="0.00923416" izz="0.0431093" />
</inertial>
</link>

<link name="upper_leg_v2_2">
<visual>
<origin xyz="0 0.8 0" rpy="1.5708 1.5708 0" />
<geometry>
<mesh filename="package://upper_leg_v2.stl"/>
</geometry>
<material name="upper_leg_v2_material">
<color rgba="0.615686 0.811765 0.929412 1.0"/>
</material>
</visual>
<collision>
<origin xyz="0 0.8 0" rpy="1.5708 1.5708 0" />
<geometry>
<mesh filename="package://upper_leg_v2.stl"/>
</geometry>
<material name="upper_leg_v2_material">
<color rgba="0.615686 0.811765 0.929412 1.0"/>
</material>
</collision>
<inertial>
<origin xyz="6.34561e-18 0.380741 0.00760038" rpy="0 0 0"/>
<mass value="60.2057" />
<inertia ixx="0.417664" ixy="0.351619"  ixz="-6.43513e-34" iyy="3.33483" iyz="-5.41754e-34" izz="3.36634" />
</inertial>
</link>

<link name="knee_2">
<visual>
<origin xyz="0.1 -0.1 -0.05" rpy="-1.5708 2.3623e-32 0" />
<geometry>
<mesh filename="package://knee.stl"/>
</geometry>
<material name="knee_material">
<color rgba="0.615686 0.811765 0.929412 1.0"/>
</material>
</visual>
<collision>
<origin xyz="0.1 -0.1 -0.05" rpy="-1.5708 2.3623e-32 0" />
<geometry>
<mesh filename="package://knee.stl"/>
</geometry>
<material name="knee_material">
<color rgba="0.615686 0.811765 0.929412 1.0"/>
</material>
</collision>
<inertial>
<origin xyz="0.0942625 0.579418 -0.05" rpy="0 0 0"/>
<mass value="109.213" />
<inertia ixx="15.8239" ixy="0.363072"  ixz="-5.99837e-17" iyy="0.595768" iyz="2.53423e-15" izz="15.935" />
</inertial>
</link>

<joint name="left_knee" type="revolute">
<origin xyz="0.05 0.7 0.1" rpy="1.77799e-16 1.5708 0" />
<parent link="upper_leg_v2_2" />
<child link="knee_2" />
<axis xyz="0 0 1"/>
<limit effort="2000" velocity="20" lower="0" upper="3.05433"/>
<joint_properties friction="0.0"/>
</joint>

<joint name="left_leg3" type="revolute">
<origin xyz="0 5.42934e-18 -0.15" rpy="-1.5708 -9.20484e-16 8.78695e-16" />
<parent link="joint_flat_2" />
<child link="upper_leg_v2_2" />
<axis xyz="0 0 1"/>
<limit effort="1000" velocity="20" lower="-1.5708" upper="0.785398"/>
<joint_properties friction="0.0"/>
</joint>

<joint name="left_leg2" type="revolute">
<origin xyz="8.1566e-19 0.11 -0.11" rpy="1.5708 1.5708 0" />
<parent link="hip_joint_2" />
<child link="joint_flat_2" />
<axis xyz="0 0 1"/>
<limit effort="1000" velocity="20" lower="-0.785398" upper="0.174533"/>
<joint_properties friction="0.0"/>
</joint>

<joint name="left_leg1" type="revolute">
<origin xyz="0.15 0 0.1" rpy="-1.5708 -0 1.5708" />
<parent link="hips_v2" />
<child link="hip_joint_2" />
<axis xyz="0 0 1"/>
<limit effort="1000" velocity="20" lower="-1.5708" upper="3.14159"/>
<joint_properties friction="0.0"/>
</joint>

<link name="joint_flat_3">
<visual>
<origin xyz="0 6.12323e-18 0" rpy="3.14159 -0 0" />
<geometry>
<mesh filename="package://joint_flat.stl"/>
</geometry>
<material name="joint_flat_material">
<color rgba="0.615686 0.811765 0.929412 1.0"/>
</material>
</visual>
<collision>
<origin xyz="0 6.12323e-18 0" rpy="3.14159 -0 0" />
<geometry>
<mesh filename="package://joint_flat.stl"/>
</geometry>
<material name="joint_flat_material">
<color rgba="0.615686 0.811765 0.929412 1.0"/>
</material>
</collision>
<inertial>
<origin xyz="-1.83967e-18 0.0279294 -0.0956494" rpy="0 0 0"/>
<mass value="10.8856" />
<inertia ixx="0.0674171" ixy="0"  ixz="0" iyy="0.0759085" iyz="0.00923416" izz="0.0431093" />
</inertial>
</link>

<link name="lower_leg_v3">
<visual>
<origin xyz="0 1.25 0" rpy="1.5708 -0 0" />
<geometry>
<mesh filename="package://lower_leg_v3.stl"/>
</geometry>
<material name="lower_leg_v3_material">
<color rgba="0.615686 0.811765 0.929412 1.0"/>
</material>
</visual>
<collision>
<origin xyz="0 1.25 0" rpy="1.5708 -0 0" />
<geometry>
<mesh filename="package://lower_leg_v3.stl"/>
</geometry>
<material name="lower_leg_v3_material">
<color rgba="0.615686 0.811765 0.929412 1.0"/>
</material>
</collision>
<inertial>
<origin xyz="-2.38221e-18 0.666261 -0.00276778" rpy="0 0 0"/>
<mass value="109.846" />
<inertia ixx="16.0959" ixy="0"  ixz="-1.61533e-16" iyy="0.539905" iyz="-0.195273" izz="16.0967" />
</inertial>
</link>

<joint name="spine2" type="revolute">
<origin xyz="0 6.12323e-18 -0.15" rpy="-1.5708 -0 0" />
<parent link="joint_flat_3" />
<child link="lower_leg_v3" />
<axis xyz="0 0 1"/>
<limit effort="600" velocity="20" lower="-1.0472" upper="1.0472"/>
<joint_properties friction="0.0"/>
</joint>

<joint name="spine1" type="revolute">
<origin xyz="0 6.12323e-18 0.25" rpy="3.14159 -0 1.5708" />
<parent link="hips_v2" />
<child link="joint_flat_3" />
<axis xyz="0 0 1"/>
<limit effort="600" velocity="20" lower="-0.523599" upper="0.523599"/>
<joint_properties friction="0.0"/>
</joint>


</robot>
