<robot name="onshape">
<link name="base">
<visual>
<origin xyz="0.00501772 0.53722 0.0387786" rpy="0 -0 3.14159" />
<geometry>
<mesh filename="package://base.stl"/>
</geometry>
<material name="base_material">
<color rgba="0.615686 0.811765 0.929412 1.0"/>
</material>
</visual>
<collision>
<origin xyz="0.00501772 0.53722 0.0387786" rpy="0 -0 3.14159" />
<geometry>
<mesh filename="package://base.stl"/>
</geometry>
<material name="base_material">
<color rgba="0.615686 0.811765 0.929412 1.0"/>
</material>
</collision>
<inertial>
<origin xyz="0 0 0" rpy="0 0 0"/>
<mass value="0" />
<inertia ixx="0" ixy="0"  ixz="0" iyy="0" iyz="0" izz="0" />
</inertial>
</link>

<link name="part_1">
<visual>
<origin xyz="1.38778e-17 -0.075 8.67362e-19" rpy="0 1.22465e-16 2.73691e-48" />
<geometry>
<mesh filename="package://part_1.stl"/>
</geometry>
<material name="part_1_material">
<color rgba="0.615686 0.811765 0.929412 1.0"/>
</material>
</visual>
<collision>
<origin xyz="1.38778e-17 -0.075 8.67362e-19" rpy="0 1.22465e-16 2.73691e-48" />
<geometry>
<mesh filename="package://part_1.stl"/>
</geometry>
<material name="part_1_material">
<color rgba="0.615686 0.811765 0.929412 1.0"/>
</material>
</collision>
<inertial>
<origin xyz="1.03136e-17 -0.028125 -0.0126452" rpy="0 0 0"/>
<mass value="4.05265" />
<inertia ixx="0.00634122" ixy="-1.17268e-19"  ixz="-7.93606e-20" iyy="0.0041645" iyz="0.000957567" izz="0.00698925" />
</inertial>
</link>

<link name="link_v2">
<visual>
<origin xyz="8.67362e-19 0 -0.5" rpy="1.5708 -0 6.59329e-33" />
<geometry>
<mesh filename="package://link_v2.stl"/>
</geometry>
<material name="link_v2_material">
<color rgba="0.615686 0.811765 0.929412 1.0"/>
</material>
</visual>
<collision>
<origin xyz="8.67362e-19 0 -0.5" rpy="1.5708 -0 6.59329e-33" />
<geometry>
<mesh filename="package://link_v2.stl"/>
</geometry>
<material name="link_v2_material">
<color rgba="0.615686 0.811765 0.929412 1.0"/>
</material>
</collision>
<inertial>
<origin xyz="0.00155634 3.39676e-19 -0.2725" rpy="0 0 0"/>
<mass value="0.680678" />
<inertia ixx="0.0176816" ixy="0"  ixz="-0.000283974" iyy="0.01768" iyz="0" izz="0.000843963" />
</inertial>
</link>

<link name="part_1_2">
<visual>
<origin xyz="1.38778e-17 -0.075 8.67362e-19" rpy="0 1.22465e-16 0" />
<geometry>
<mesh filename="package://part_1.stl"/>
</geometry>
<material name="part_1_material">
<color rgba="0.615686 0.811765 0.929412 1.0"/>
</material>
</visual>
<collision>
<origin xyz="1.38778e-17 -0.075 8.67362e-19" rpy="0 1.22465e-16 0" />
<geometry>
<mesh filename="package://part_1.stl"/>
</geometry>
<material name="part_1_material">
<color rgba="0.615686 0.811765 0.929412 1.0"/>
</material>
</collision>
<inertial>
<origin xyz="1.03136e-17 -0.028125 -0.0126452" rpy="0 0 0"/>
<mass value="4.05265" />
<inertia ixx="0.00634122" ixy="-1.17268e-19"  ixz="-7.93606e-20" iyy="0.0041645" iyz="0.000957567" izz="0.00698925" />
</inertial>
</link>

<link name="link_v2_2">
<visual>
<origin xyz="0 0 -0.5" rpy="1.5708 -0 -1.71907e-48" />
<geometry>
<mesh filename="package://link_v2.stl"/>
</geometry>
<material name="link_v2_material">
<color rgba="0.615686 0.811765 0.929412 1.0"/>
</material>
</visual>
<collision>
<origin xyz="0 0 -0.5" rpy="1.5708 -0 -1.71907e-48" />
<geometry>
<mesh filename="package://link_v2.stl"/>
</geometry>
<material name="link_v2_material">
<color rgba="0.615686 0.811765 0.929412 1.0"/>
</material>
</collision>
<inertial>
<origin xyz="0.00155634 3.39676e-19 -0.2725" rpy="0 0 0"/>
<mass value="0.680678" />
<inertia ixx="0.0176816" ixy="0"  ixz="-0.000283974" iyy="0.01768" iyz="0" izz="0.000843963" />
</inertial>
</link>

<joint name="joint4" type="revolute">
<origin xyz="6.93889e-18 -0.075 4.33681e-18" rpy="-1.5708 -1.5708 0" />
<parent link="part_1_2" />
<child link="link_v2_2" />
<axis xyz="0 0 1"/>
<limit effort="1" velocity="20" />
<joint_properties friction="0.0"/>
</joint>

<joint name="joint3" type="revolute">
<origin xyz="3.46945e-18 1.38778e-17 -0.55" rpy="1.5708 7.28018e-46 1.5708" />
<parent link="link_v2" />
<child link="part_1_2" />
<axis xyz="0 0 1"/>
<limit effort="1" velocity="20" lower="-1.5708" upper="1.5708"/>
<joint_properties friction="0.0"/>
</joint>

<joint name="joint2" type="revolute">
<origin xyz="6.93889e-18 -0.075 4.33681e-18" rpy="-1.5708 1.5708 0" />
<parent link="part_1" />
<child link="link_v2" />
<axis xyz="0 0 1"/>
<limit effort="1" velocity="20" />
<joint_properties friction="0.0"/>
</joint>

<joint name="joint1" type="revolute">
<origin xyz="0.00501772 0.58722 0.0387786" rpy="-3.14159 1.5708 0" />
<parent link="base" />
<child link="part_1" />
<axis xyz="0 0 1"/>
<limit effort="1" velocity="20" lower="-1.5708" upper="1.5708"/>
<joint_properties friction="0.0"/>
</joint>


</robot>
