<robot name="onshape">
<link name="torso_quadruped">
<visual>
<origin xyz="-0.0361304 0.0304099 0.00190468" rpy="0 -0 0" />
<geometry>
<mesh filename="package://torso_quadruped.stl"/>
</geometry>
<material name="torso_quadruped_material">
<color rgba="0.615686 0.811765 0.929412 1.0"/>
</material>
</visual>
<collision>
<origin xyz="-0.0361304 0.0304099 0.00190468" rpy="0 -0 0" />
<geometry>
<mesh filename="package://torso_quadruped.stl"/>
</geometry>
<material name="torso_quadruped_material">
<color rgba="0.615686 0.811765 0.929412 1.0"/>
</material>
</collision>
<inertial>
<origin xyz="-0.0361304 0.0304099 0.0574602" rpy="0 0 0"/>
<mass value="229.022" />
<inertia ixx="14.9218" ixy="-1.12962e-16"  ixz="0" iyy="14.9218" iyz="0" izz="29.3063" />
</inertial>
</link>

<link name="shoulder">
<visual>
<origin xyz="0 6.93889e-18 0" rpy="3.14159 -0 0" />
<geometry>
<mesh filename="package://shoulder.stl"/>
</geometry>
<material name="shoulder_material">
<color rgba="0.615686 0.811765 0.929412 1.0"/>
</material>
</visual>
<collision>
<origin xyz="0 6.93889e-18 0" rpy="3.14159 -0 0" />
<geometry>
<mesh filename="package://shoulder.stl"/>
</geometry>
<material name="shoulder_material">
<color rgba="0.615686 0.811765 0.929412 1.0"/>
</material>
</collision>
<inertial>
<origin xyz="-3.73477e-19 0.0279294 -0.0956494" rpy="0 0 0"/>
<mass value="10.8856" />
<inertia ixx="0.0674171" ixy="0"  ixz="0" iyy="0.0759085" iyz="0.00923416" izz="0.0431093" />
</inertial>
</link>

<link name="upperlimb">
<visual>
<origin xyz="-5.55112e-17 0 0" rpy="1.5708 -1.38667e-32 -5.55112e-17" />
<geometry>
<mesh filename="package://upperlimb.stl"/>
</geometry>
<material name="upperlimb_material">
<color rgba="0.615686 0.811765 0.929412 1.0"/>
</material>
</visual>
<collision>
<origin xyz="-5.55112e-17 0 0" rpy="1.5708 -1.38667e-32 -5.55112e-17" />
<geometry>
<mesh filename="package://upperlimb.stl"/>
</geometry>
<material name="upperlimb_material">
<color rgba="0.615686 0.811765 0.929412 1.0"/>
</material>
</collision>
<inertial>
<origin xyz="-5.79551e-17 -0.5 -0.04186" rpy="0 0 0"/>
<mass value="48.0664" />
<inertia ixx="5.20449" ixy="-2.19701e-32"  ixz="2.93583e-16" iyy="0.150452" iyz="0" izz="5.28871" />
</inertial>
</link>

<link name="lowerlimb">
<visual>
<origin xyz="-2.22045e-16 1.525 -3.46945e-18" rpy="1.5708 -4.62223e-33 -5.55112e-17" />
<geometry>
<mesh filename="package://lowerlimb.stl"/>
</geometry>
<material name="lowerlimb_material">
<color rgba="0.615686 0.811765 0.929412 1.0"/>
</material>
</visual>
<collision>
<origin xyz="-2.22045e-16 1.525 -3.46945e-18" rpy="1.5708 -4.62223e-33 -5.55112e-17" />
<geometry>
<mesh filename="package://lowerlimb.stl"/>
</geometry>
<material name="lowerlimb_material">
<color rgba="0.615686 0.811765 0.929412 1.0"/>
</material>
</collision>
<inertial>
<origin xyz="-2.17971e-16 0.862582 -0.0299475" rpy="0 0 0"/>
<mass value="82.2783" />
<inertia ixx="21.2191" ixy="8.28968e-17"  ixz="1.18199e-15" iyy="0.329118" iyz="-0.584536" izz="21.2929" />
</inertial>
</link>

<joint name="lowerlimb1" type="revolute">
<origin xyz="5.55112e-17 -1 3.46945e-18" rpy="-3.14159 7.90733e-17 -2.44346" />
<parent link="upperlimb" />
<child link="lowerlimb" />
<axis xyz="0 0 1"/>
<limit effort="1000" velocity="20" lower="-2.0944" upper="-0.698132"/>
<joint_properties friction="0.0"/>
</joint>

<joint name="upperlimb1" type="revolute">
<origin xyz="0 6.93889e-18 -0.15" rpy="1.5708 0.349066 3.14159" />
<parent link="shoulder" />
<child link="upperlimb" />
<axis xyz="0 0 1"/>
<limit effort="1000" velocity="20" lower="-1.5708" upper="-0.349066"/>
<joint_properties friction="0.0"/>
</joint>

<joint name="shoulder1" type="revolute">
<origin xyz="0.36387 0.0304099 0.151905" rpy="3.14159 -0 0" />
<parent link="torso_quadruped" />
<child link="shoulder" />
<axis xyz="0 0 1"/>
<limit effort="1000" velocity="20" lower="-0.785398" upper="0.785398"/>
<joint_properties friction="0.0"/>
</joint>

<link name="shoulder_2">
<visual>
<origin xyz="0 6.93889e-18 0" rpy="3.14159 -0 0" />
<geometry>
<mesh filename="package://shoulder.stl"/>
</geometry>
<material name="shoulder_material">
<color rgba="0.615686 0.811765 0.929412 1.0"/>
</material>
</visual>
<collision>
<origin xyz="0 6.93889e-18 0" rpy="3.14159 -0 0" />
<geometry>
<mesh filename="package://shoulder.stl"/>
</geometry>
<material name="shoulder_material">
<color rgba="0.615686 0.811765 0.929412 1.0"/>
</material>
</collision>
<inertial>
<origin xyz="-3.73477e-19 0.0279294 -0.0956494" rpy="0 0 0"/>
<mass value="10.8856" />
<inertia ixx="0.0674171" ixy="0"  ixz="0" iyy="0.0759085" iyz="0.00923416" izz="0.0431093" />
</inertial>
</link>

<link name="upperlimb_2">
<visual>
<origin xyz="0 0 0" rpy="1.5708 -1.54074e-32 -5.55112e-17" />
<geometry>
<mesh filename="package://upperlimb.stl"/>
</geometry>
<material name="upperlimb_material">
<color rgba="0.615686 0.811765 0.929412 1.0"/>
</material>
</visual>
<collision>
<origin xyz="0 0 0" rpy="1.5708 -1.54074e-32 -5.55112e-17" />
<geometry>
<mesh filename="package://upperlimb.stl"/>
</geometry>
<material name="upperlimb_material">
<color rgba="0.615686 0.811765 0.929412 1.0"/>
</material>
</collision>
<inertial>
<origin xyz="-2.44397e-18 -0.5 -0.04186" rpy="0 0 0"/>
<mass value="48.0664" />
<inertia ixx="5.20449" ixy="-4.57946e-32"  ixz="2.93583e-16" iyy="0.150452" iyz="-1.62971e-32" izz="5.28871" />
</inertial>
</link>

<link name="lowerlimb_2">
<visual>
<origin xyz="0 1.525 0" rpy="1.5708 3.85186e-33 0" />
<geometry>
<mesh filename="package://lowerlimb.stl"/>
</geometry>
<material name="lowerlimb_material">
<color rgba="0.615686 0.811765 0.929412 1.0"/>
</material>
</visual>
<collision>
<origin xyz="0 1.525 0" rpy="1.5708 3.85186e-33 0" />
<geometry>
<mesh filename="package://lowerlimb.stl"/>
</geometry>
<material name="lowerlimb_material">
<color rgba="0.615686 0.811765 0.929412 1.0"/>
</material>
</collision>
<inertial>
<origin xyz="4.07313e-18 0.862582 -0.0299475" rpy="0 0 0"/>
<mass value="82.2783" />
<inertia ixx="21.2191" ixy="1.15345e-16"  ixz="2.25155e-33" iyy="0.329118" iyz="-0.584536" izz="21.2929" />
</inertial>
</link>

<joint name="lowerlimb2" type="revolute">
<origin xyz="1.11022e-16 -1 -6.93889e-18" rpy="-3.14159 7.90733e-17 -2.44346" />
<parent link="upperlimb_2" />
<child link="lowerlimb_2" />
<axis xyz="0 0 1"/>
<limit effort="1000" velocity="20" lower="-2.0944" upper="-0.698132"/>
<joint_properties friction="0.0"/>
</joint>

<joint name="upperlimb2" type="revolute">
<origin xyz="0 6.93889e-18 -0.15" rpy="1.5708 0.349066 3.14159" />
<parent link="shoulder_2" />
<child link="upperlimb_2" />
<axis xyz="0 0 1"/>
<limit effort="1000" velocity="20" lower="-1.5708" upper="-0.349066"/>
<joint_properties friction="0.0"/>
</joint>

<joint name="shoulder2" type="revolute">
<origin xyz="-0.0361304 0.43041 0.151905" rpy="3.14159 -0 1.5708" />
<parent link="torso_quadruped" />
<child link="shoulder_2" />
<axis xyz="0 0 1"/>
<limit effort="1000" velocity="20" lower="-0.785398" upper="0.785398"/>
<joint_properties friction="0.0"/>
</joint>

<link name="shoulder_3">
<visual>
<origin xyz="0 6.93889e-18 0" rpy="3.14159 -0 0" />
<geometry>
<mesh filename="package://shoulder.stl"/>
</geometry>
<material name="shoulder_material">
<color rgba="0.615686 0.811765 0.929412 1.0"/>
</material>
</visual>
<collision>
<origin xyz="0 6.93889e-18 0" rpy="3.14159 -0 0" />
<geometry>
<mesh filename="package://shoulder.stl"/>
</geometry>
<material name="shoulder_material">
<color rgba="0.615686 0.811765 0.929412 1.0"/>
</material>
</collision>
<inertial>
<origin xyz="-3.73477e-19 0.0279294 -0.0956494" rpy="0 0 0"/>
<mass value="10.8856" />
<inertia ixx="0.0674171" ixy="0"  ixz="0" iyy="0.0759085" iyz="0.00923416" izz="0.0431093" />
</inertial>
</link>

<link name="upperlimb_3">
<visual>
<origin xyz="5.55112e-17 1 0" rpy="1.5708 -6.16298e-33 -5.55112e-17" />
<geometry>
<mesh filename="package://upperlimb.stl"/>
</geometry>
<material name="upperlimb_material">
<color rgba="0.615686 0.811765 0.929412 1.0"/>
</material>
</visual>
<collision>
<origin xyz="5.55112e-17 1 0" rpy="1.5708 -6.16298e-33 -5.55112e-17" />
<geometry>
<mesh filename="package://upperlimb.stl"/>
</geometry>
<material name="upperlimb_material">
<color rgba="0.615686 0.811765 0.929412 1.0"/>
</material>
</collision>
<inertial>
<origin xyz="5.30672e-17 0.5 -0.04186" rpy="0 0 0"/>
<mass value="48.0664" />
<inertia ixx="5.20449" ixy="4.90399e-32"  ixz="2.93583e-16" iyy="0.150452" iyz="-1.62971e-32" izz="5.28871" />
</inertial>
</link>

<link name="lowerlimb_3">
<visual>
<origin xyz="2.22045e-16 1.525 0" rpy="1.5708 -0 -5.55112e-17" />
<geometry>
<mesh filename="package://lowerlimb.stl"/>
</geometry>
<material name="lowerlimb_material">
<color rgba="0.615686 0.811765 0.929412 1.0"/>
</material>
</visual>
<collision>
<origin xyz="2.22045e-16 1.525 0" rpy="1.5708 -0 -5.55112e-17" />
<geometry>
<mesh filename="package://lowerlimb.stl"/>
</geometry>
<material name="lowerlimb_material">
<color rgba="0.615686 0.811765 0.929412 1.0"/>
</material>
</collision>
<inertial>
<origin xyz="2.26118e-16 0.862582 -0.0299475" rpy="0 0 0"/>
<mass value="82.2783" />
<inertia ixx="21.2191" ixy="8.28968e-17"  ixz="1.18199e-15" iyy="0.329118" iyz="-0.584536" izz="21.2929" />
</inertial>
</link>

<joint name="lowerlimb3" type="revolute">
<origin xyz="5.55112e-17 1 -6.93889e-18" rpy="3.14159 4.33914e-17 0.698132" />
<parent link="upperlimb_3" />
<child link="lowerlimb_3" />
<axis xyz="0 0 1"/>
<limit effort="1000" velocity="20" lower="-2.0944" upper="-0.698132"/>
<joint_properties friction="0.0"/>
</joint>

<joint name="upperlimb3" type="revolute">
<origin xyz="-5.55112e-17 6.93889e-18 -0.15" rpy="-1.5708 -0.349066 6.51621e-17" />
<parent link="shoulder_3" />
<child link="upperlimb_3" />
<axis xyz="0 0 1"/>
<limit effort="1000" velocity="20" lower="-1.5708" upper="-0.349066"/>
<joint_properties friction="0.0"/>
</joint>

<joint name="shoulder3" type="revolute">
<origin xyz="-0.0361304 -0.36959 0.151905" rpy="3.14159 -0 -1.5708" />
<parent link="torso_quadruped" />
<child link="shoulder_3" />
<axis xyz="0 0 1"/>
<limit effort="1000" velocity="20" lower="-0.785398" upper="0.785398"/>
<joint_properties friction="0.0"/>
</joint>

<link name="shoulder_4">
<visual>
<origin xyz="0 6.93889e-18 0" rpy="3.14159 -0 0" />
<geometry>
<mesh filename="package://shoulder.stl"/>
</geometry>
<material name="shoulder_material">
<color rgba="0.615686 0.811765 0.929412 1.0"/>
</material>
</visual>
<collision>
<origin xyz="0 6.93889e-18 0" rpy="3.14159 -0 0" />
<geometry>
<mesh filename="package://shoulder.stl"/>
</geometry>
<material name="shoulder_material">
<color rgba="0.615686 0.811765 0.929412 1.0"/>
</material>
</collision>
<inertial>
<origin xyz="-3.73477e-19 0.0279294 -0.0956494" rpy="0 0 0"/>
<mass value="10.8856" />
<inertia ixx="0.0674171" ixy="0"  ixz="0" iyy="0.0759085" iyz="0.00923416" izz="0.0431093" />
</inertial>
</link>

<link name="upperlimb_4">
<visual>
<origin xyz="0 1 -3.46945e-18" rpy="1.5708 -6.16298e-33 -5.55112e-17" />
<geometry>
<mesh filename="package://upperlimb.stl"/>
</geometry>
<material name="upperlimb_material">
<color rgba="0.615686 0.811765 0.929412 1.0"/>
</material>
</visual>
<collision>
<origin xyz="0 1 -3.46945e-18" rpy="1.5708 -6.16298e-33 -5.55112e-17" />
<geometry>
<mesh filename="package://upperlimb.stl"/>
</geometry>
<material name="upperlimb_material">
<color rgba="0.615686 0.811765 0.929412 1.0"/>
</material>
</collision>
<inertial>
<origin xyz="-2.44397e-18 0.5 -0.04186" rpy="0 0 0"/>
<mass value="48.0664" />
<inertia ixx="5.20449" ixy="4.90399e-32"  ixz="2.93583e-16" iyy="0.150452" iyz="-1.62971e-32" izz="5.28871" />
</inertial>
</link>

<link name="lowerlimb_4">
<visual>
<origin xyz="2.22045e-16 1.525 0" rpy="1.5708 6.16298e-33 0" />
<geometry>
<mesh filename="package://lowerlimb.stl"/>
</geometry>
<material name="lowerlimb_material">
<color rgba="0.615686 0.811765 0.929412 1.0"/>
</material>
</visual>
<collision>
<origin xyz="2.22045e-16 1.525 0" rpy="1.5708 6.16298e-33 0" />
<geometry>
<mesh filename="package://lowerlimb.stl"/>
</geometry>
<material name="lowerlimb_material">
<color rgba="0.615686 0.811765 0.929412 1.0"/>
</material>
</collision>
<inertial>
<origin xyz="2.26118e-16 0.862582 -0.0299475" rpy="0 0 0"/>
<mass value="82.2783" />
<inertia ixx="21.2191" ixy="1.15345e-16"  ixz="3.60248e-33" iyy="0.329118" iyz="-0.584536" izz="21.2929" />
</inertial>
</link>

<joint name="lowerlimb4" type="revolute">
<origin xyz="2.77556e-16 1 3.46945e-18" rpy="3.14159 4.33914e-17 0.698132" />
<parent link="upperlimb_4" />
<child link="lowerlimb_4" />
<axis xyz="0 0 1"/>
<limit effort="1000" velocity="20" lower="-2.0944" upper="-0.698132"/>
<joint_properties friction="0.0"/>
</joint>

<joint name="upperlimb4" type="revolute">
<origin xyz="-5.55112e-17 6.93889e-18 -0.15" rpy="-1.5708 -0.349066 6.51621e-17" />
<parent link="shoulder_4" />
<child link="upperlimb_4" />
<axis xyz="0 0 1"/>
<limit effort="1000" velocity="20" lower="-1.5708" upper="-0.349066"/>
<joint_properties friction="0.0"/>
</joint>

<joint name="shoulder4" type="revolute">
<origin xyz="-0.43613 0.0304099 0.151905" rpy="3.14159 -0 3.14159" />
<parent link="torso_quadruped" />
<child link="shoulder_4" />
<axis xyz="0 0 1"/>
<limit effort="1000" velocity="20" lower="-0.785398" upper="0.785398"/>
<joint_properties friction="0.0"/>
</joint>


</robot>
